"""
Error Handling and Disaster Recovery Integration Tests

This module implements comprehensive integration tests for error handling and
disaster recovery scenarios in the FileWallBall system.

Test Coverage:
- Database connection failure scenarios
- Redis connection interruption handling
- File system capacity exhaustion tests
- Network timeout simulation
- Service communication failure tests
- Graceful shutdown verification
- Circuit breaker behavior testing
- Error recovery and resilience validation
"""

import asyncio
import os
import signal
import tempfile
import time
from pathlib import Path
from typing import AsyncGenerator, Dict, List
from unittest.mock import AsyncMock, MagicMock, patch

import httpx
import pytest
import pytest_asyncio
from fastapi import HTTPException
from fastapi.testclient import TestClient
from redis.asyncio import Redis
from sqlalchemy import create_engine, text
from sqlalchemy.exc import DisconnectionError, OperationalError
from sqlalchemy.orm import sessionmaker

from app.core.config import TestingConfig
from app.database import get_db
from app.main import app
from app.models.database import Base
from app.services.cache_service import CacheService
from app.services.error_handler_service import ErrorHandlerService
from app.services.file_service import FileService
from app.services.redis_connection_manager import CircuitBreaker, RedisConnectionManager


class TestErrorHandlingDisasterRecovery:
    """Error handling and disaster recovery integration tests."""

    @pytest_asyncio.fixture
    async def error_handler_service(self) -> ErrorHandlerService:
        """Create error handler service for testing."""
        return ErrorHandlerService()

    @pytest_asyncio.fixture
    async def circuit_breaker(self) -> CircuitBreaker:
        """Create circuit breaker for testing."""
        return CircuitBreaker(failure_threshold=3, recovery_timeout=5)

    @pytest_asyncio.fixture
    async def redis_connection_manager(self) -> RedisConnectionManager:
        """Create Redis connection manager for testing."""
        return RedisConnectionManager()

    @pytest.fixture
    def test_error_scenarios(self) -> Dict[str, Dict]:
        """Define comprehensive error scenarios for testing."""
        return {
            "database_connection_failure": {
                "description": "Database connection failure scenarios",
                "scenarios": [
                    "connection_timeout",
                    "connection_refused",
                    "database_unavailable",
                    "connection_pool_exhaustion",
                    "transaction_timeout",
                ],
                "expected_behavior": {
                    "graceful_degradation": True,
                    "proper_error_response": True,
                    "no_data_loss": True,
                    "recovery_mechanism": True,
                },
            },
            "redis_connection_failure": {
                "description": "Redis connection failure scenarios",
                "scenarios": [
                    "redis_unavailable",
                    "connection_timeout",
                    "memory_exhaustion",
                    "network_partition",
                    "circuit_breaker_activation",
                ],
                "expected_behavior": {
                    "fallback_to_database": True,
                    "circuit_breaker_works": True,
                    "graceful_degradation": True,
                    "automatic_recovery": True,
                },
            },
            "file_system_failures": {
                "description": "File system failure scenarios",
                "scenarios": [
                    "disk_space_full",
                    "permission_denied",
                    "file_system_corruption",
                    "io_error",
                    "path_not_found",
                ],
                "expected_behavior": {
                    "proper_error_handling": True,
                    "data_integrity_preserved": True,
                    "graceful_failure": True,
                    "recovery_possible": True,
                },
            },
            "network_failures": {
                "description": "Network failure scenarios",
                "scenarios": [
                    "timeout_error",
                    "connection_reset",
                    "dns_failure",
                    "proxy_failure",
                    "rate_limiting",
                ],
                "expected_behavior": {
                    "retry_mechanism": True,
                    "timeout_handling": True,
                    "fallback_strategy": True,
                    "user_friendly_error": True,
                },
            },
            "service_failures": {
                "description": "Service communication failure scenarios",
                "scenarios": [
                    "service_unavailable",
                    "service_timeout",
                    "service_crash",
                    "load_balancer_failure",
                    "dependency_failure",
                ],
                "expected_behavior": {
                    "circuit_breaker_activation": True,
                    "fallback_service": True,
                    "graceful_degradation": True,
                    "automatic_recovery": True,
                },
            },
        }

    @pytest_asyncio.fixture
    async def mock_failing_database(self, test_db_engine):
        """Create a mock database that can simulate failures."""
        # Create a real database engine that we can control
        from app.core.config import TestingConfig
        config = TestingConfig()
        engine = create_engine(
            config.database_url,
            pool_size=1,
            max_overflow=0,
        )

        # Create tables
        Base.metadata.create_all(bind=engine)

        # Create session factory
        TestingSessionLocal = sessionmaker(
            autocommit=False, autoflush=False, bind=engine
        )

        return {
            "engine": engine,
            "session_factory": TestingSessionLocal,
            "is_failing": False,
            "failure_type": None,
        }

    @pytest_asyncio.fixture
    async def mock_failing_redis(self, test_redis_client):
        """Create a mock Redis client that can simulate failures."""
        return {
            "client": test_redis_client,
            "is_failing": False,
            "failure_type": None,
            "failure_count": 0,
        }

    @pytest_asyncio.fixture
    def temp_full_disk(self):
        """Create a temporary directory that simulates a full disk."""
        with tempfile.TemporaryDirectory() as temp_dir:
            # Create a large file to simulate disk space usage
            large_file = Path(temp_dir) / "large_file.bin"
            try:
                # Try to create a large file (this might fail on some systems)
                with open(large_file, "wb") as f:
                    f.write(b"0" * 1024 * 1024)  # 1MB
            except OSError:
                # If we can't create a large file, we'll simulate disk full differently
                pass

            yield temp_dir

    async def test_database_connection_failure_scenarios(
        self, mock_failing_database, error_handler_service, test_client
    ):
        """Test database connection failure scenarios."""

        # Test 1: Connection timeout
        mock_failing_database["is_failing"] = True
        mock_failing_database["failure_type"] = "timeout"

        with patch("app.database.get_db") as mock_get_db:
            mock_get_db.side_effect = OperationalError("Connection timeout", None, None)

            response = test_client.get("/api/v1/files")
            assert response.status_code in [500, 503]
            assert (
                "database" in response.text.lower()
                or "timeout" in response.text.lower()
            )

        # Test 2: Connection refused
        mock_failing_database["failure_type"] = "refused"

        with patch("app.database.get_db") as mock_get_db:
            mock_get_db.side_effect = DisconnectionError(
                "Connection refused", None, None
            )

            response = test_client.get("/api/v1/files")
            assert response.status_code in [500, 503]
            assert (
                "database" in response.text.lower()
                or "connection" in response.text.lower()
            )

        # Test 3: Database unavailable
        mock_failing_database["failure_type"] = "unavailable"

        with patch("app.database.get_db") as mock_get_db:
            mock_get_db.side_effect = Exception("Database server is down")

            response = test_client.get("/api/v1/files")
            assert response.status_code == 500

        # Test 4: Connection pool exhaustion
        mock_failing_database["failure_type"] = "pool_exhaustion"

        with patch("app.database.get_db") as mock_get_db:
            mock_get_db.side_effect = OperationalError(
                "QueuePool limit of size 5 overflow 10 reached", None, None
            )

            response = test_client.get("/api/v1/files")
            assert response.status_code in [500, 503]

        # Test 5: Transaction timeout
        mock_failing_database["failure_type"] = "transaction_timeout"

        with patch("app.database.get_db") as mock_get_db:
            mock_get_db.side_effect = OperationalError(
                "Transaction timeout", None, None
            )

            response = test_client.get("/api/v1/files")
            assert response.status_code in [500, 503]

    async def test_redis_connection_failure_scenarios(
        self, mock_failing_redis, circuit_breaker, test_client
    ):
        """Test Redis connection failure scenarios."""

        # Test 1: Redis unavailable
        mock_failing_redis["is_failing"] = True
        mock_failing_redis["failure_type"] = "unavailable"

        with patch(
            "app.services.cache_service.get_redis_manager"
        ) as mock_redis_manager:
            mock_client = AsyncMock()
            mock_client.ping.side_effect = Exception("Redis server is down")
            mock_redis_manager.return_value.get_client.return_value = mock_client

            response = test_client.get("/api/v1/files")
            # Should still work with fallback to database
            assert response.status_code in [200, 500]

        # Test 2: Connection timeout
        mock_failing_redis["failure_type"] = "timeout"

        with patch(
            "app.services.cache_service.get_redis_manager"
        ) as mock_redis_manager:
            mock_client = AsyncMock()
            mock_client.ping.side_effect = Exception("Connection timeout")
            mock_redis_manager.return_value.get_client.return_value = mock_client

            response = test_client.get("/api/v1/files")
            assert response.status_code in [200, 500]

        # Test 3: Memory exhaustion
        mock_failing_redis["failure_type"] = "memory_exhaustion"

        with patch(
            "app.services.cache_service.get_redis_manager"
        ) as mock_redis_manager:
            mock_client = AsyncMock()
            mock_client.set.side_effect = Exception("OOM command not allowed")
            mock_redis_manager.return_value.get_client.return_value = mock_client

            response = test_client.get("/api/v1/files")
            assert response.status_code in [200, 500]

        # Test 4: Network partition
        mock_failing_redis["failure_type"] = "network_partition"

        with patch(
            "app.services.cache_service.get_redis_manager"
        ) as mock_redis_manager:
            mock_client = AsyncMock()
            mock_client.ping.side_effect = Exception("Connection reset by peer")
            mock_redis_manager.return_value.get_client.return_value = mock_client

            response = test_client.get("/api/v1/files")
            assert response.status_code in [200, 500]

        # Test 5: Circuit breaker activation
        mock_failing_redis["failure_type"] = "circuit_breaker"

        # Simulate multiple failures to trigger circuit breaker
        for _ in range(5):
            circuit_breaker.record_failure()

        assert circuit_breaker.state == "OPEN"
        assert not circuit_breaker.can_execute()

        # Wait for recovery timeout
        await asyncio.sleep(6)  # recovery_timeout + 1

        assert circuit_breaker.state == "HALF_OPEN"
        assert circuit_breaker.can_execute()

    async def test_file_system_failure_scenarios(
        self, temp_full_disk, error_handler_service, test_client
    ):
        """Test file system failure scenarios."""

        # Test 1: Disk space full
        with patch("app.services.file_service.Path") as mock_path:
            mock_path.return_value.exists.return_value = True
            mock_path.return_value.stat.return_value = MagicMock(
                st_size=1024 * 1024 * 1024  # 1GB
            )

            # Mock disk space check to return full
            with patch("shutil.disk_usage") as mock_disk_usage:
                mock_disk_usage.return_value = (1024, 0, 0)  # No free space

                response = test_client.post(
                    "/api/v1/files/upload",
                    files={"file": ("test.txt", b"test content")},
                )
                assert response.status_code in [
                    507,
                    500,
                ]  # Insufficient Storage or Internal Server Error

        # Test 2: Permission denied
        with patch("app.services.file_service.Path") as mock_path:
            mock_path.return_value.mkdir.side_effect = PermissionError(
                "Permission denied"
            )

            response = test_client.post(
                "/api/v1/files/upload", files={"file": ("test.txt", b"test content")}
            )
            assert response.status_code in [403, 500]

        # Test 3: File system corruption
        with patch("app.services.file_service.Path") as mock_path:
            mock_path.return_value.exists.return_value = True
            mock_path.return_value.open.side_effect = OSError("File system error")

            response = test_client.get("/api/v1/files")
            assert response.status_code in [500, 503]

        # Test 4: IO Error
        with patch("app.services.file_service.Path") as mock_path:
            mock_path.return_value.open.side_effect = IOError("Input/output error")

            response = test_client.post(
                "/api/v1/files/upload", files={"file": ("test.txt", b"test content")}
            )
            assert response.status_code in [500, 503]

        # Test 5: Path not found
        with patch("app.services.file_service.Path") as mock_path:
            mock_path.return_value.exists.return_value = False
            mock_path.return_value.mkdir.side_effect = FileNotFoundError(
                "Directory not found"
            )

            response = test_client.post(
                "/api/v1/files/upload", files={"file": ("test.txt", b"test content")}
            )
            assert response.status_code in [500, 503]

    async def test_network_failure_scenarios(self, test_client):
        """Test network failure scenarios."""

        # Test 1: Timeout error
        with patch("httpx.AsyncClient.get") as mock_get:
            mock_get.side_effect = httpx.TimeoutException("Request timeout")

            response = test_client.get("/api/v1/files")
            assert response.status_code in [500, 503]

        # Test 2: Connection reset
        with patch("httpx.AsyncClient.get") as mock_get:
            mock_get.side_effect = httpx.ConnectError("Connection reset by peer")

            response = test_client.get("/api/v1/files")
            assert response.status_code in [500, 503]

        # Test 3: DNS failure
        with patch("httpx.AsyncClient.get") as mock_get:
            mock_get.side_effect = httpx.ConnectError("Name or service not known")

            response = test_client.get("/api/v1/files")
            assert response.status_code in [500, 503]

        # Test 4: Proxy failure
        with patch("httpx.AsyncClient.get") as mock_get:
            mock_get.side_effect = httpx.ProxyError("Proxy connection failed")

            response = test_client.get("/api/v1/files")
            assert response.status_code in [500, 503]

        # Test 5: Rate limiting
        with patch("httpx.AsyncClient.get") as mock_get:
            mock_response = MagicMock()
            mock_response.status_code = 429
            mock_response.text = "Too Many Requests"
            mock_get.return_value = mock_response

            response = test_client.get("/api/v1/files")
            assert response.status_code in [429, 500]

    async def test_service_failure_scenarios(self, test_client):
        """Test service communication failure scenarios."""

        # Test 1: Service unavailable
        with patch("app.services.file_service.FileService.get_files") as mock_get_files:
            mock_get_files.side_effect = Exception("Service unavailable")

            response = test_client.get("/api/v1/files")
            assert response.status_code in [500, 503]

        # Test 2: Service timeout
        with patch("app.services.file_service.FileService.get_files") as mock_get_files:
            mock_get_files.side_effect = asyncio.TimeoutError("Service timeout")

            response = test_client.get("/api/v1/files")
            assert response.status_code in [500, 503]

        # Test 3: Service crash
        with patch("app.services.file_service.FileService.get_files") as mock_get_files:
            mock_get_files.side_effect = SystemExit("Service crashed")

            response = test_client.get("/api/v1/files")
            assert response.status_code in [500, 503]

        # Test 4: Load balancer failure
        with patch("app.services.file_service.FileService.get_files") as mock_get_files:
            mock_get_files.side_effect = ConnectionError("Load balancer failure")

            response = test_client.get("/api/v1/files")
            assert response.status_code in [500, 503]

        # Test 5: Dependency failure
        with patch("app.services.file_service.FileService.get_files") as mock_get_files:
            mock_get_files.side_effect = Exception("Database dependency failed")

            response = test_client.get("/api/v1/files")
            assert response.status_code in [500, 503]

    async def test_graceful_shutdown_verification(self, test_client):
        """Test graceful shutdown verification."""

        # Test 1: Signal handling
        with patch("signal.signal") as mock_signal:
            # Simulate SIGTERM signal
            mock_signal.return_value = None

            # This test verifies that the application can handle shutdown signals
            # In a real scenario, we would send SIGTERM to the process
            assert True  # Placeholder for signal handling verification

        # Test 2: Connection cleanup
        with patch("app.database.get_db") as mock_get_db:
            mock_session = MagicMock()
            mock_get_db.return_value = mock_session

            response = test_client.get("/api/v1/files")

            # Verify that session is properly managed
            assert response.status_code in [200, 500]

        # Test 3: Resource cleanup
        with patch("app.services.cache_service.CacheService.close") as mock_close:
            # Simulate application shutdown
            mock_close.return_value = None

            # This test verifies that resources are properly cleaned up
            assert True  # Placeholder for resource cleanup verification

        # Test 4: Pending request handling
        with patch("asyncio.create_task") as mock_create_task:
            # Simulate pending requests during shutdown
            mock_create_task.return_value = None

            response = test_client.get("/api/v1/files")
            assert response.status_code in [200, 500]

        # Test 5: Health check during shutdown
        response = test_client.get("/health")
        assert response.status_code in [200, 503]  # Should return 503 during shutdown

    async def test_circuit_breaker_behavior_testing(self, circuit_breaker, test_client):
        """Test circuit breaker behavior."""

        # Test 1: Circuit breaker state transitions
        assert circuit_breaker.state == "CLOSED"
        assert circuit_breaker.can_execute()

        # Simulate failures
        for _ in range(3):
            circuit_breaker.record_failure()

        assert circuit_breaker.state == "OPEN"
        assert not circuit_breaker.can_execute()

        # Wait for recovery timeout
        await asyncio.sleep(6)  # recovery_timeout + 1

        assert circuit_breaker.state == "HALF_OPEN"
        assert circuit_breaker.can_execute()

        # Simulate success
        circuit_breaker.record_success()
        assert circuit_breaker.state == "CLOSED"
        assert circuit_breaker.can_execute()

        # Test 2: Circuit breaker with Redis operations
        with patch(
            "app.services.cache_service.get_redis_manager"
        ) as mock_redis_manager:
            mock_client = AsyncMock()
            mock_client.ping.side_effect = Exception("Redis error")
            mock_redis_manager.return_value.get_client.return_value = mock_client

            # Multiple requests should trigger circuit breaker
            for _ in range(5):
                response = test_client.get("/api/v1/files")
                assert response.status_code in [200, 500]

        # Test 3: Circuit breaker recovery
        with patch(
            "app.services.cache_service.get_redis_manager"
        ) as mock_redis_manager:
            mock_client = AsyncMock()
            mock_client.ping.return_value = True  # Redis is back
            mock_redis_manager.return_value.get_client.return_value = mock_client

            response = test_client.get("/api/v1/files")
            assert response.status_code in [200, 500]

        # Test 4: Circuit breaker configuration
        custom_circuit_breaker = CircuitBreaker(failure_threshold=2, recovery_timeout=3)

        assert custom_circuit_breaker.failure_threshold == 2
        assert custom_circuit_breaker.recovery_timeout == 3

        # Test 5: Circuit breaker metrics
        circuit_breaker.failure_count = 0
        circuit_breaker.success_count = 0

        # Simulate some operations
        for _ in range(3):
            circuit_breaker.record_failure()

        assert circuit_breaker.failure_count == 3
        assert circuit_breaker.state == "OPEN"

    async def test_error_recovery_and_resilience_validation(
        self, error_handler_service, test_client
    ):
        """Test error recovery and resilience validation."""

        # Test 1: Error classification
        error = HTTPException(status_code=400, detail="Bad Request")
        error_result = await error_handler_service.handle_upload_error(
            error=error,
            file_uuid="test-uuid",
            request=MagicMock(),
            context={"test": "data"},
        )

        assert "error_type" in error_result
        assert "error_message" in error_result
        assert "status_code" in error_result
        assert "is_retryable" in error_result

        # Test 2: Retry mechanism
        with patch("app.services.file_service.FileService.upload_file") as mock_upload:
            mock_upload.side_effect = [Exception("Temporary error"), "success"]

            # First attempt should fail
            response1 = test_client.post(
                "/api/v1/files/upload", files={"file": ("test.txt", b"test content")}
            )
            assert response1.status_code in [500, 503]

            # Second attempt should succeed (in a real retry scenario)
            response2 = test_client.post(
                "/api/v1/files/upload", files={"file": ("test.txt", b"test content")}
            )
            # Note: This is a simplified test - real retry logic would be more complex

        # Test 3: Data integrity preservation
        with patch("app.services.file_service.FileService.upload_file") as mock_upload:
            mock_upload.side_effect = Exception("Upload failed")

            response = test_client.post(
                "/api/v1/files/upload", files={"file": ("test.txt", b"test content")}
            )

            # Verify that no partial data was saved
            assert response.status_code in [500, 503]

        # Test 4: Graceful degradation
        with patch("app.services.cache_service.CacheService.get_file_info") as mock_get:
            mock_get.side_effect = Exception("Cache unavailable")

            # Should fallback to database
            response = test_client.get("/api/v1/files")
            assert response.status_code in [200, 500]

        # Test 5: Error logging and monitoring
        with patch(
            "app.services.error_handler_service.ErrorHandlerService._log_error"
        ) as mock_log:
            mock_log.return_value = {"error_id": "test-error-id"}

            error = Exception("Test error")
            error_result = await error_handler_service.handle_upload_error(
                error=error,
                file_uuid="test-uuid",
                request=MagicMock(),
                context={"test": "data"},
            )

            assert "error_id" in error_result
            mock_log.assert_called_once()

    async def test_performance_under_failure_conditions(self, test_client):
        """Test system performance under failure conditions."""

        # Test 1: Response time under database failure
        start_time = time.time()

        with patch("app.database.get_db") as mock_get_db:
            mock_get_db.side_effect = OperationalError("Database error", None, None)

            response = test_client.get("/api/v1/files")
            end_time = time.time()

            response_time = end_time - start_time
            assert response_time < 5.0  # Should respond within 5 seconds
            assert response.status_code in [500, 503]

        # Test 2: Response time under Redis failure
        start_time = time.time()

        with patch(
            "app.services.cache_service.get_redis_manager"
        ) as mock_redis_manager:
            mock_client = AsyncMock()
            mock_client.ping.side_effect = Exception("Redis error")
            mock_redis_manager.return_value.get_client.return_value = mock_client

            response = test_client.get("/api/v1/files")
            end_time = time.time()

            response_time = end_time - start_time
            assert response_time < 3.0  # Should respond within 3 seconds
            assert response.status_code in [200, 500]

        # Test 3: Concurrent requests under failure
        async def make_concurrent_requests():
            with patch("app.database.get_db") as mock_get_db:
                mock_get_db.side_effect = OperationalError("Database error", None, None)

                tasks = []
                for _ in range(10):
                    task = asyncio.create_task(
                        asyncio.to_thread(test_client.get, "/api/v1/files")
                    )
                    tasks.append(task)

                responses = await asyncio.gather(*tasks, return_exceptions=True)
                return responses

        responses = await make_concurrent_requests()

        # All requests should complete (even if with errors)
        assert len(responses) == 10
        for response in responses:
            if not isinstance(response, Exception):
                assert response.status_code in [500, 503]

        # Test 4: Memory usage under failure
        import os

        import psutil

        process = psutil.Process(os.getpid())
        initial_memory = process.memory_info().rss

        # Simulate multiple failures
        for _ in range(100):
            with patch("app.database.get_db") as mock_get_db:
                mock_get_db.side_effect = OperationalError("Database error", None, None)
                test_client.get("/api/v1/files")

        final_memory = process.memory_info().rss
        memory_increase = final_memory - initial_memory

        # Memory increase should be reasonable (less than 50MB)
        assert memory_increase < 50 * 1024 * 1024

        # Test 5: Recovery time measurement
        start_time = time.time()

        # Simulate service recovery
        with patch("app.database.get_db") as mock_get_db:
            # First call fails
            mock_get_db.side_effect = [
                OperationalError("Database error", None, None),
                MagicMock(),
            ]

            # First request should fail
            response1 = test_client.get("/api/v1/files")
            assert response1.status_code in [500, 503]

            # Second request should succeed
            response2 = test_client.get("/api/v1/files")
            assert response2.status_code in [200, 500]

        recovery_time = time.time() - start_time
        assert recovery_time < 10.0  # Recovery should be quick

    async def test_comprehensive_disaster_recovery_scenarios(
        self, test_error_scenarios, error_handler_service, circuit_breaker, test_client
    ):
        """Test comprehensive disaster recovery scenarios."""

        # Test 1: Multiple simultaneous failures
        with (
            patch("app.database.get_db") as mock_db,
            patch("app.services.cache_service.get_redis_manager") as mock_redis,
        ):

            mock_db.side_effect = OperationalError("Database error", None, None)
            mock_client = AsyncMock()
            mock_client.ping.side_effect = Exception("Redis error")
            mock_redis.return_value.get_client.return_value = mock_client

            response = test_client.get("/api/v1/files")
            assert response.status_code in [500, 503]

        # Test 2: Cascading failure scenarios
        with patch("app.services.file_service.FileService.upload_file") as mock_upload:
            mock_upload.side_effect = [
                OperationalError("Database error", None, None),
                Exception("Cache error"),
                "success",
            ]

            # First attempt: Database failure
            response1 = test_client.post(
                "/api/v1/files/upload", files={"file": ("test.txt", b"test content")}
            )
            assert response1.status_code in [500, 503]

            # Second attempt: Cache failure
            response2 = test_client.post(
                "/api/v1/files/upload", files={"file": ("test.txt", b"test content")}
            )
            assert response2.status_code in [500, 503]

        # Test 3: Recovery verification
        with patch("app.database.get_db") as mock_db:
            # Simulate recovery
            mock_db.side_effect = [
                OperationalError("Database error", None, None),
                MagicMock(),
            ]

            # Failed request
            response1 = test_client.get("/api/v1/files")
            assert response1.status_code in [500, 503]

            # Successful request after recovery
            response2 = test_client.get("/api/v1/files")
            assert response2.status_code in [200, 500]

        # Test 4: Error scenario validation
        for scenario_name, scenario_config in test_error_scenarios.items():
            assert "description" in scenario_config
            assert "scenarios" in scenario_config
            assert "expected_behavior" in scenario_config

            # Verify that all expected behaviors are defined
            expected_behaviors = scenario_config["expected_behavior"]
            assert isinstance(expected_behaviors, dict)
            assert len(expected_behaviors) > 0

        # Test 5: System resilience validation
        # This test verifies that the system can handle multiple types of failures
        # and still provide some level of service

        failure_scenarios = [
            ("database", OperationalError("Database error", None, None)),
            ("redis", Exception("Redis error")),
            ("filesystem", OSError("Disk full")),
            ("network", ConnectionError("Network error")),
        ]

        for failure_type, exception in failure_scenarios:
            with patch("app.database.get_db") as mock_db:
                if failure_type == "database":
                    mock_db.side_effect = exception
                else:
                    mock_db.side_effect = MagicMock()

                response = test_client.get("/api/v1/files")

                # System should respond (even if with error)
                assert response.status_code is not None
                assert response.status_code in [200, 500, 503]
