"""
Error Handling and Disaster Recovery Unit Tests (Core Logic)

This module implements unit tests for error handling and disaster recovery
scenarios in the FileWallBall system, with mocked external dependencies.

Test Coverage:
- Database connection failure scenarios (mocked)
- Redis connection interruption handling (mocked)
- File system capacity exhaustion tests (mocked)
- Network timeout simulation (mocked)
- Service communication failure tests (mocked)
- Graceful shutdown verification (mocked)
- Circuit breaker behavior testing
- Error recovery and resilience validation (mocked)
"""

import asyncio
import time
from pathlib import Path
from typing import Dict
from unittest.mock import AsyncMock, MagicMock, patch

import httpx
import pytest
import pytest_asyncio
from fastapi import HTTPException
from sqlalchemy.exc import DisconnectionError, OperationalError

from app.services.cache_service import CacheService
from app.services.error_handler_service import ErrorHandlerService
from app.services.file_service import FileService
from app.services.redis_connection_manager import CircuitBreaker


class TestErrorHandlingDisasterRecoveryCore:
    """Error handling and disaster recovery unit tests (core logic)."""

    @pytest_asyncio.fixture
    async def error_handler_service(self, mock_db_session) -> ErrorHandlerService:
        """Create error handler service for testing."""
        return ErrorHandlerService(db_session=mock_db_session)

    @pytest_asyncio.fixture
    async def circuit_breaker(self) -> CircuitBreaker:
        """Create circuit breaker for testing."""
        return CircuitBreaker(failure_threshold=3, recovery_timeout=5)

    @pytest_asyncio.fixture
    async def mock_redis_client(self) -> AsyncMock:
        """Create mock Redis client for testing."""
        return AsyncMock()

    @pytest_asyncio.fixture
    async def cache_service(self, mock_redis_client) -> CacheService:
        """Create cache service with mock Redis client."""
        with patch("app.services.cache_service.get_redis_manager") as mock_manager:
            mock_manager.return_value.get_client.return_value = mock_redis_client
            return CacheService()

    @pytest_asyncio.fixture
    async def mock_db_session(self) -> MagicMock:
        """Create mock database session for testing."""
        return MagicMock()

    @pytest_asyncio.fixture
    async def file_service(self, mock_db_session) -> FileService:
        """Create file service with mocked dependencies."""
        return FileService(db_session=mock_db_session)

    @pytest.fixture
    def test_error_scenarios(self) -> Dict[str, Dict]:
        """Define comprehensive error scenarios for testing."""
        return {
            "database_connection_failure": {
                "description": "Database connection failure scenarios",
                "scenarios": [
                    "connection_timeout",
                    "connection_refused",
                    "database_unavailable",
                    "connection_pool_exhaustion",
                    "transaction_timeout",
                ],
                "expected_behavior": {
                    "graceful_degradation": True,
                    "proper_error_response": True,
                    "no_data_loss": True,
                    "recovery_mechanism": True,
                },
            },
            "redis_connection_failure": {
                "description": "Redis connection failure scenarios",
                "scenarios": [
                    "redis_unavailable",
                    "connection_timeout",
                    "memory_exhaustion",
                    "network_partition",
                    "circuit_breaker_activation",
                ],
                "expected_behavior": {
                    "fallback_to_database": True,
                    "circuit_breaker_works": True,
                    "graceful_degradation": True,
                    "automatic_recovery": True,
                },
            },
            "file_system_failures": {
                "description": "File system failure scenarios",
                "scenarios": [
                    "disk_space_full",
                    "permission_denied",
                    "file_system_corruption",
                    "io_error",
                    "path_not_found",
                ],
                "expected_behavior": {
                    "proper_error_handling": True,
                    "data_integrity_preserved": True,
                    "graceful_failure": True,
                    "recovery_possible": True,
                },
            },
            "network_failures": {
                "description": "Network failure scenarios",
                "scenarios": [
                    "timeout_error",
                    "connection_reset",
                    "dns_failure",
                    "proxy_failure",
                    "rate_limiting",
                ],
                "expected_behavior": {
                    "retry_mechanism": True,
                    "timeout_handling": True,
                    "fallback_strategy": True,
                    "user_friendly_error": True,
                },
            },
            "service_failures": {
                "description": "Service communication failure scenarios",
                "scenarios": [
                    "service_unavailable",
                    "service_timeout",
                    "service_crash",
                    "load_balancer_failure",
                    "dependency_failure",
                ],
                "expected_behavior": {
                    "circuit_breaker_activation": True,
                    "fallback_service": True,
                    "graceful_degradation": True,
                    "automatic_recovery": True,
                },
            },
        }

    async def test_database_connection_failure_scenarios(
        self, error_handler_service, file_service
    ):
        """Test database connection failure scenarios."""

        # Test 1: Connection timeout
        with patch.object(file_service.db_session, "query") as mock_query:
            mock_query.side_effect = OperationalError("Connection timeout", None, None)

            with pytest.raises(OperationalError):
                await file_service.get_files()

        # Test 2: Connection refused
        with patch.object(file_service.db_session, "query") as mock_query:
            mock_query.side_effect = DisconnectionError(
                "Connection refused", None, None
            )

            with pytest.raises(DisconnectionError):
                await file_service.get_files()

        # Test 3: Database unavailable
        with patch.object(file_service.db_session, "query") as mock_query:
            mock_query.side_effect = Exception("Database server is down")

            with pytest.raises(Exception):
                await file_service.get_files()

        # Test 4: Connection pool exhaustion
        with patch.object(file_service.db_session, "query") as mock_query:
            mock_query.side_effect = OperationalError(
                "QueuePool limit of size 5 overflow 10 reached", None, None
            )

            with pytest.raises(OperationalError):
                await file_service.get_files()

        # Test 5: Transaction timeout
        with patch.object(file_service.db_session, "query") as mock_query:
            mock_query.side_effect = OperationalError("Transaction timeout", None, None)

            with pytest.raises(OperationalError):
                await file_service.get_files()

    async def test_redis_connection_failure_scenarios(
        self, cache_service, circuit_breaker
    ):
        """Test Redis connection failure scenarios."""

        # Test 1: Redis unavailable
        cache_service.client.ping.side_effect = Exception("Redis server is down")

        with pytest.raises(Exception):
            await cache_service.client.ping()

        # Test 2: Connection timeout
        cache_service.client.ping.side_effect = Exception("Connection timeout")

        with pytest.raises(Exception):
            await cache_service.client.ping()

        # Test 3: Memory exhaustion
        cache_service.client.set.side_effect = Exception("OOM command not allowed")

        with pytest.raises(Exception):
            await cache_service.client.set("test_key", "test_value")

        # Test 4: Network partition
        cache_service.client.ping.side_effect = Exception("Connection reset by peer")

        with pytest.raises(Exception):
            await cache_service.client.ping()

        # Test 5: Circuit breaker activation
        # Simulate multiple failures to trigger circuit breaker
        for _ in range(5):
            circuit_breaker.record_failure()

        assert circuit_breaker.state == "OPEN"
        assert not circuit_breaker.can_execute()

        # Wait for recovery timeout
        await asyncio.sleep(6)  # recovery_timeout + 1

        assert circuit_breaker.state == "HALF_OPEN"
        assert circuit_breaker.can_execute()

    async def test_file_system_failure_scenarios(
        self, file_service, error_handler_service
    ):
        """Test file system failure scenarios."""

        # Test 1: Disk space full
        with (
            patch("pathlib.Path.exists") as mock_exists,
            patch("pathlib.Path.stat") as mock_stat,
            patch("shutil.disk_usage") as mock_disk_usage,
        ):

            mock_exists.return_value = True
            mock_stat.return_value = MagicMock(st_size=1024 * 1024 * 1024)  # 1GB
            mock_disk_usage.return_value = (1024, 0, 0)  # No free space

            with pytest.raises(OSError):
                # Simulate disk full error
                raise OSError("No space left on device")

        # Test 2: Permission denied
        with patch("pathlib.Path.mkdir") as mock_mkdir:
            mock_mkdir.side_effect = PermissionError("Permission denied")

            with pytest.raises(PermissionError):
                file_service.upload_dir.mkdir(parents=True, exist_ok=True)

        # Test 3: File system corruption
        with (
            patch("pathlib.Path.exists") as mock_exists,
            patch("pathlib.Path.open") as mock_open,
        ):

            mock_exists.return_value = True
            mock_open.side_effect = OSError("File system error")

            with pytest.raises(OSError):
                with open(file_service.upload_dir / "test.txt", "r"):
                    pass

        # Test 4: IO Error
        with patch("pathlib.Path.open") as mock_open:
            mock_open.side_effect = IOError("Input/output error")

            with pytest.raises(IOError):
                with open(file_service.upload_dir / "test.txt", "w"):
                    pass

        # Test 5: Path not found
        with (
            patch("pathlib.Path.exists") as mock_exists,
            patch("pathlib.Path.mkdir") as mock_mkdir,
        ):

            mock_exists.return_value = False
            mock_mkdir.side_effect = FileNotFoundError("Directory not found")

            with pytest.raises(FileNotFoundError):
                file_service.upload_dir.mkdir(parents=True, exist_ok=True)

    async def test_network_failure_scenarios(self):
        """Test network failure scenarios."""

        # Test 1: Timeout error
        with patch("httpx.AsyncClient.get") as mock_get:
            mock_get.side_effect = httpx.TimeoutException("Request timeout")

            with pytest.raises(httpx.TimeoutException):
                async with httpx.AsyncClient() as client:
                    await client.get("http://test.com")

        # Test 2: Connection reset
        with patch("httpx.AsyncClient.get") as mock_get:
            mock_get.side_effect = httpx.ConnectError("Connection reset by peer")

            with pytest.raises(httpx.ConnectError):
                async with httpx.AsyncClient() as client:
                    await client.get("http://test.com")

        # Test 3: DNS failure
        with patch("httpx.AsyncClient.get") as mock_get:
            mock_get.side_effect = httpx.ConnectError("Name or service not known")

            with pytest.raises(httpx.ConnectError):
                async with httpx.AsyncClient() as client:
                    await client.get("http://test.com")

        # Test 4: Proxy failure
        with patch("httpx.AsyncClient.get") as mock_get:
            mock_get.side_effect = httpx.ProxyError("Proxy connection failed")

            with pytest.raises(httpx.ProxyError):
                async with httpx.AsyncClient() as client:
                    await client.get("http://test.com")

        # Test 5: Rate limiting
        with patch("httpx.AsyncClient.get") as mock_get:
            mock_response = MagicMock()
            mock_response.status_code = 429
            mock_response.text = "Too Many Requests"
            mock_get.return_value = mock_response

            async with httpx.AsyncClient() as client:
                response = await client.get("http://test.com")
                assert response.status_code == 429

    async def test_service_failure_scenarios(self, file_service):
        """Test service communication failure scenarios."""

        # Test 1: Service unavailable
        with patch.object(file_service, "get_files") as mock_get_files:
            mock_get_files.side_effect = Exception("Service unavailable")

            with pytest.raises(Exception):
                await file_service.get_files()

        # Test 2: Service timeout
        with patch.object(file_service, "get_files") as mock_get_files:
            mock_get_files.side_effect = asyncio.TimeoutError("Service timeout")

            with pytest.raises(asyncio.TimeoutError):
                await file_service.get_files()

        # Test 3: Service crash
        with patch.object(file_service, "get_files") as mock_get_files:
            mock_get_files.side_effect = SystemExit("Service crashed")

            with pytest.raises(SystemExit):
                await file_service.get_files()

        # Test 4: Load balancer failure
        with patch.object(file_service, "get_files") as mock_get_files:
            mock_get_files.side_effect = ConnectionError("Load balancer failure")

            with pytest.raises(ConnectionError):
                await file_service.get_files()

        # Test 5: Dependency failure
        with patch.object(file_service, "get_files") as mock_get_files:
            mock_get_files.side_effect = Exception("Database dependency failed")

            with pytest.raises(Exception):
                await file_service.get_files()

    async def test_graceful_shutdown_verification(self, cache_service, file_service):
        """Test graceful shutdown verification."""

        # Test 1: Signal handling
        with patch("signal.signal") as mock_signal:
            # Simulate SIGTERM signal
            mock_signal.return_value = None

            # This test verifies that the application can handle shutdown signals
            # In a real scenario, we would send SIGTERM to the process
            assert True  # Placeholder for signal handling verification

        # Test 2: Connection cleanup
        with patch.object(file_service.db_session, "close") as mock_close:
            # Simulate session cleanup
            mock_close.return_value = None

            # Verify that session cleanup is called
            file_service.db_session.close()
            mock_close.assert_called_once()

        # Test 3: Resource cleanup
        with patch.object(cache_service, "close") as mock_close:
            # Simulate application shutdown
            mock_close.return_value = None

            # This test verifies that resources are properly cleaned up
            assert True  # Placeholder for resource cleanup verification

        # Test 4: Pending request handling
        with patch("asyncio.create_task") as mock_create_task:
            # Simulate pending requests during shutdown
            mock_create_task.return_value = None

            # This test verifies that pending requests are handled properly
            assert True  # Placeholder for pending request verification

        # Test 5: Health check during shutdown
        # This would test the health endpoint during shutdown
        assert True  # Placeholder for health check verification

    async def test_circuit_breaker_behavior_testing(self, circuit_breaker):
        """Test circuit breaker behavior."""

        # Test 1: Circuit breaker state transitions
        assert circuit_breaker.state == "CLOSED"
        assert circuit_breaker.can_execute()

        # Simulate failures
        for _ in range(3):
            circuit_breaker.record_failure()

        assert circuit_breaker.state == "OPEN"
        assert not circuit_breaker.can_execute()

        # Wait for recovery timeout
        await asyncio.sleep(6)  # recovery_timeout + 1

        assert circuit_breaker.state == "HALF_OPEN"
        assert circuit_breaker.can_execute()

        # Simulate success
        circuit_breaker.record_success()
        assert circuit_breaker.state == "CLOSED"
        assert circuit_breaker.can_execute()

        # Test 2: Circuit breaker with Redis operations
        with patch(
            "app.services.cache_service.get_redis_manager"
        ) as mock_redis_manager:
            mock_client = AsyncMock()
            mock_client.ping.side_effect = Exception("Redis error")
            mock_redis_manager.return_value.get_client.return_value = mock_client

            # Multiple operations should trigger circuit breaker
            for _ in range(5):
                with pytest.raises(Exception):
                    await mock_client.ping()

        # Test 3: Circuit breaker recovery
        with patch(
            "app.services.cache_service.get_redis_manager"
        ) as mock_redis_manager:
            mock_client = AsyncMock()
            mock_client.ping.return_value = True  # Redis is back
            mock_redis_manager.return_value.get_client.return_value = mock_client

            # Should work after recovery
            result = await mock_client.ping()
            assert result is True

        # Test 4: Circuit breaker configuration
        custom_circuit_breaker = CircuitBreaker(failure_threshold=2, recovery_timeout=3)

        assert custom_circuit_breaker.failure_threshold == 2
        assert custom_circuit_breaker.recovery_timeout == 3

        # Test 5: Circuit breaker metrics
        circuit_breaker.failure_count = 0

        # Simulate some operations
        for _ in range(3):
            circuit_breaker.record_failure()

        assert circuit_breaker.failure_count == 3
        assert circuit_breaker.state == "OPEN"

    async def test_error_recovery_and_resilience_validation(
        self, error_handler_service
    ):
        """Test error recovery and resilience validation."""

        # Test 1: Error classification
        error = HTTPException(status_code=400, detail="Bad Request")
        error_result = await error_handler_service.handle_upload_error(
            error=error,
            file_uuid="test-uuid",
            request=MagicMock(),
            context={"test": "data"},
        )

        assert "error_type" in error_result
        assert "error_message" in error_result
        assert "status_code" in error_result
        assert "is_retryable" in error_result

        # Test 2: Retry mechanism
        with patch.object(FileService, "upload_file") as mock_upload:
            mock_upload.side_effect = [Exception("Temporary error"), "success"]

            # First attempt should fail
            with pytest.raises(Exception):
                await mock_upload("test_file")

            # Second attempt should succeed (in a real retry scenario)
            result = await mock_upload("test_file")
            assert result == "success"

        # Test 3: Data integrity preservation
        with patch.object(FileService, "upload_file") as mock_upload:
            mock_upload.side_effect = Exception("Upload failed")

            with pytest.raises(Exception):
                await mock_upload("test_file")

            # Verify that no partial data was saved
            # This would be verified by checking the file system state

        # Test 4: Graceful degradation
        with patch.object(CacheService, "get_file_info") as mock_get:
            mock_get.side_effect = Exception("Cache unavailable")

            # Should fallback to database
            with pytest.raises(Exception):
                await mock_get("test_key")

        # Test 5: Error logging and monitoring
        with patch.object(ErrorHandlerService, "_log_error") as mock_log:
            mock_log.return_value = {"error_id": "test-error-id"}

            error = Exception("Test error")
            error_result = await error_handler_service.handle_upload_error(
                error=error,
                file_uuid="test-uuid",
                request=MagicMock(),
                context={"test": "data"},
            )

            assert "error_id" in error_result
            mock_log.assert_called_once()

    async def test_performance_under_failure_conditions(self):
        """Test system performance under failure conditions."""

        # Test 1: Response time under database failure
        start_time = time.time()

        with patch("app.database.get_db") as mock_get_db:
            mock_get_db.side_effect = OperationalError("Database error", None, None)

            with pytest.raises(OperationalError):
                mock_get_db()

            end_time = time.time()
            response_time = end_time - start_time

            assert response_time < 1.0  # Should respond within 1 second

        # Test 2: Response time under Redis failure
        start_time = time.time()

        with patch(
            "app.services.cache_service.get_redis_manager"
        ) as mock_redis_manager:
            mock_client = AsyncMock()
            mock_client.ping.side_effect = Exception("Redis error")
            mock_redis_manager.return_value.get_client.return_value = mock_client

            with pytest.raises(Exception):
                await mock_client.ping()

            end_time = time.time()
            response_time = end_time - start_time

            assert response_time < 1.0  # Should respond within 1 second

        # Test 3: Concurrent requests under failure
        async def make_concurrent_requests():
            with patch("app.database.get_db") as mock_get_db:
                mock_get_db.side_effect = OperationalError("Database error", None, None)

                tasks = []
                for _ in range(10):
                    task = asyncio.create_task(asyncio.to_thread(lambda: mock_get_db()))
                    tasks.append(task)

                responses = await asyncio.gather(*tasks, return_exceptions=True)
                return responses

        responses = await make_concurrent_requests()

        # All requests should complete (even if with errors)
        assert len(responses) == 10
        for response in responses:
            assert isinstance(response, OperationalError)

        # Test 4: Memory usage under failure
        import os

        import psutil

        process = psutil.Process(os.getpid())
        initial_memory = process.memory_info().rss

        # Simulate multiple failures
        for _ in range(100):
            with patch("app.database.get_db") as mock_get_db:
                mock_get_db.side_effect = OperationalError("Database error", None, None)
                try:
                    mock_get_db()
                except OperationalError:
                    pass

        final_memory = process.memory_info().rss
        memory_increase = final_memory - initial_memory

        # Memory increase should be reasonable (less than 50MB)
        assert memory_increase < 50 * 1024 * 1024

        # Test 5: Recovery time measurement
        start_time = time.time()

        # Simulate service recovery
        with patch("app.database.get_db") as mock_get_db:
            # First call fails
            mock_get_db.side_effect = [
                OperationalError("Database error", None, None),
                MagicMock(),
            ]

            # First request should fail
            with pytest.raises(OperationalError):
                mock_get_db()

            # Second request should succeed
            result = mock_get_db()
            assert result is not None

        recovery_time = time.time() - start_time
        assert recovery_time < 5.0  # Recovery should be quick

    async def test_comprehensive_disaster_recovery_scenarios(
        self, test_error_scenarios, error_handler_service, circuit_breaker
    ):
        """Test comprehensive disaster recovery scenarios."""

        # Test 1: Multiple simultaneous failures
        with (
            patch("app.database.get_db") as mock_db,
            patch("app.services.cache_service.get_redis_manager") as mock_redis,
        ):

            mock_db.side_effect = OperationalError("Database error", None, None)
            mock_client = AsyncMock()
            mock_client.ping.side_effect = Exception("Redis error")
            mock_redis.return_value.get_client.return_value = mock_client

            # Both database and Redis should fail
            with pytest.raises(OperationalError):
                mock_db()

            with pytest.raises(Exception):
                await mock_client.ping()

        # Test 2: Cascading failure scenarios
        with patch.object(FileService, "upload_file") as mock_upload:
            mock_upload.side_effect = [
                OperationalError("Database error", None, None),
                Exception("Cache error"),
                "success",
            ]

            # First attempt: Database failure
            with pytest.raises(OperationalError):
                await mock_upload("test_file")

            # Second attempt: Cache failure
            with pytest.raises(Exception):
                await mock_upload("test_file")

            # Third attempt: Success
            result = await mock_upload("test_file")
            assert result == "success"

        # Test 3: Recovery verification
        with patch("app.database.get_db") as mock_db:
            # Simulate recovery
            mock_db.side_effect = [
                OperationalError("Database error", None, None),
                MagicMock(),
            ]

            # Failed request
            with pytest.raises(OperationalError):
                mock_db()

            # Successful request after recovery
            result = mock_db()
            assert result is not None

        # Test 4: Error scenario validation
        for scenario_name, scenario_config in test_error_scenarios.items():
            assert "description" in scenario_config
            assert "scenarios" in scenario_config
            assert "expected_behavior" in scenario_config

            # Verify that all expected behaviors are defined
            expected_behaviors = scenario_config["expected_behavior"]
            assert isinstance(expected_behaviors, dict)
            assert len(expected_behaviors) > 0

        # Test 5: System resilience validation
        # This test verifies that the system can handle multiple types of failures
        # and still provide some level of service

        failure_scenarios = [
            ("database", OperationalError("Database error", None, None)),
            ("redis", Exception("Redis error")),
            ("filesystem", OSError("Disk full")),
            ("network", ConnectionError("Network error")),
        ]

        for failure_type, exception in failure_scenarios:
            with patch("app.database.get_db") as mock_db:
                if failure_type == "database":
                    mock_db.side_effect = exception
                else:
                    mock_db.side_effect = MagicMock()

                # System should handle the failure appropriately
                if failure_type == "database":
                    with pytest.raises(OperationalError):
                        mock_db()
                else:
                    result = mock_db()
                    assert result is not None
